============================= test session starts ==============================
platform linux2 -- Python 2.7.15+, pytest-3.10.1, py-1.8.0, pluggy-0.12.0
rootdir: /media/an0nym0us/Essentilas/University/semester-3/data-structures/course-assignments/assignment6, inifile:
plugins: timeout-1.3.3
timeout: 3.0s
timeout method: signal
timeout func_only: False
collected 11 items

test_student.py .F..FFFFFFF                                              [100%]

=================================== FAILURES ===================================
______________________________ test_s_find_val_1 _______________________________

    def test_s_find_val_1():
        t_d = get_hier()
        node = t_d.find_val('Director')
>       assert str(node.val) == 'Director'
E       AttributeError: 'NoneType' object has no attribute 'val'

test_student.py:69: AttributeError
______________________________ test_s_find_val_4 _______________________________

    def test_s_find_val_4():
        t_d = get_hier_2()
        node = t_d.find_val('Account 1')
>       assert str(node.val) == 'Account 1'
E       AttributeError: 'NoneType' object has no attribute 'val'

test_student.py:86: AttributeError
______________________________ test_s_find_val_5 _______________________________

    def test_s_find_val_5():
        t_d = get_hier_2()
        node = t_d.find_val('Account 2')
>       assert str(node.val) == 'Account 2'
E       AttributeError: 'NoneType' object has no attribute 'val'

test_student.py:92: AttributeError
______________________________ test_s_collector_1 ______________________________

    def test_s_collector_1():
        t_d = get_hier()
        c = Collector()
>       t_d.left.dfs_apply(c.process)
E       AttributeError: Collector instance has no attribute 'process'

test_student.py:106: AttributeError
______________________________ test_s_collector_2 ______________________________

    def test_s_collector_2():
        t_d = get_hier()
        c = Collector()
>       t_d.left.left.dfs_apply(c.process)
E       AttributeError: Collector instance has no attribute 'process'

test_student.py:112: AttributeError
______________________________ test_s_hierarchy_1 ______________________________

    def test_s_hierarchy_1():
        t_d = get_hier()
        l = t_d.find_people_in_hierarchy('Director')
>       assert l == ['Director', 'HoD 1', 'CS 1', 'CS 2', 'HoD 2', 'EE 1', 'EE 2']
E       AssertionError: assert None == ['Director', 'HoD 1', 'CS 1', 'CS 2', 'HoD 2', 'EE 1', ...]

test_student.py:119: AssertionError
______________________________ test_s_hierarchy_2 ______________________________

    def test_s_hierarchy_2():
        t_d = get_hier()
        l = t_d.find_people_in_hierarchy('HoD 2')
>       assert l == ['HoD 2', 'EE 1', 'EE 2']
E       AssertionError: assert None == ['HoD 2', 'EE 1', 'EE 2']

test_student.py:125: AssertionError
______________________________ test_s_hierarchy_3 ______________________________

    def test_s_hierarchy_3():
        t_d = get_hier()
        try:
            t_d.find_people_in_hierarchy('Accountant')
>           raise AssertionError("Expecting a ValueError when node is not found.")
E           AssertionError: Expecting a ValueError when node is not found.

test_student.py:132: AssertionError
====================== 8 failed, 3 passed in 0.74 seconds ======================
============================= test session starts ==============================
platform linux -- Python 3.7.3, pytest-3.10.1, py-1.8.0, pluggy-0.12.0
rootdir: /media/an0nym0us/Essentilas/University/semester-3/data-structures/course-assignments/assignment6, inifile:
plugins: doctestplus-0.3.0, remotedata-0.3.1, openfiles-0.3.2, arraydiff-0.3, timeout-1.3.3
timeout: 3.0s
timeout method: signal
timeout func_only: False
collected 11 items

test_student.py ......FFFFF                                              [100%]

=================================== FAILURES ===================================
______________________________ test_s_collector_1 ______________________________

    def test_s_collector_1():
        t_d = get_hier()
        c = Collector()
>       t_d.left.dfs_apply(c.process)
E       AttributeError: 'Collector' object has no attribute 'process'

test_student.py:106: AttributeError
______________________________ test_s_collector_2 ______________________________

    def test_s_collector_2():
        t_d = get_hier()
        c = Collector()
>       t_d.left.left.dfs_apply(c.process)
E       AttributeError: 'Collector' object has no attribute 'process'

test_student.py:112: AttributeError
______________________________ test_s_hierarchy_1 ______________________________

    def test_s_hierarchy_1():
        t_d = get_hier()
        l = t_d.find_people_in_hierarchy('Director')
>       assert l == ['Director', 'HoD 1', 'CS 1', 'CS 2', 'HoD 2', 'EE 1', 'EE 2']
E       AssertionError: assert None == ['Director', 'HoD 1', 'CS 1', 'CS 2', 'HoD 2', 'EE 1', ...]

test_student.py:119: AssertionError
______________________________ test_s_hierarchy_2 ______________________________

    def test_s_hierarchy_2():
        t_d = get_hier()
        l = t_d.find_people_in_hierarchy('HoD 2')
>       assert l == ['HoD 2', 'EE 1', 'EE 2']
E       AssertionError: assert None == ['HoD 2', 'EE 1', 'EE 2']

test_student.py:125: AssertionError
______________________________ test_s_hierarchy_3 ______________________________

    def test_s_hierarchy_3():
        t_d = get_hier()
        try:
            t_d.find_people_in_hierarchy('Accountant')
>           raise AssertionError("Expecting a ValueError when node is not found.")
E           AssertionError: Expecting a ValueError when node is not found.

test_student.py:132: AssertionError
====================== 5 failed, 6 passed in 0.33 seconds ======================
============================= test session starts ==============================
platform linux -- Python 3.7.3, pytest-3.10.1, py-1.8.0, pluggy-0.12.0
rootdir: /media/an0nym0us/Essentilas/University/semester-3/data-structures/course-assignments/assignment6, inifile:
plugins: doctestplus-0.3.0, remotedata-0.3.1, openfiles-0.3.2, arraydiff-0.3, timeout-1.3.3
timeout: 3.0s
timeout method: signal
timeout func_only: False
collected 11 items

test_student.py ......FFFFF                                              [100%]

=================================== FAILURES ===================================
______________________________ test_s_collector_1 ______________________________

    def test_s_collector_1():
        t_d = get_hier()
        c = Collector()
        t_d.left.dfs_apply(c.process)
>       assert c.get_list()  == ['HoD 1', 'CS 1', 'CS 2']
E       AssertionError: assert [<a06.Person ...7fb81f5fadd8>] == ['HoD 1', 'CS 1', 'CS 2']
E         At index 0 diff: <a06.Person object at 0x7fb81f5fad68> != 'HoD 1'
E         Use -v to get the full diff

test_student.py:107: AssertionError
______________________________ test_s_collector_2 ______________________________

    def test_s_collector_2():
        t_d = get_hier()
        c = Collector()
        t_d.left.left.dfs_apply(c.process)
>       assert c.get_list()  == ['CS 1']
E       AssertionError: assert [<a06.Person ...7fb81f5b8240>] == ['CS 1']
E         At index 0 diff: <a06.Person object at 0x7fb81f5b8240> != 'CS 1'
E         Use -v to get the full diff

test_student.py:113: AssertionError
______________________________ test_s_hierarchy_1 ______________________________

    def test_s_hierarchy_1():
        t_d = get_hier()
        l = t_d.find_people_in_hierarchy('Director')
>       assert l == ['Director', 'HoD 1', 'CS 1', 'CS 2', 'HoD 2', 'EE 1', 'EE 2']
E       AssertionError: assert None == ['Director', 'HoD 1', 'CS 1', 'CS 2', 'HoD 2', 'EE 1', ...]

test_student.py:119: AssertionError
______________________________ test_s_hierarchy_2 ______________________________

    def test_s_hierarchy_2():
        t_d = get_hier()
        l = t_d.find_people_in_hierarchy('HoD 2')
>       assert l == ['HoD 2', 'EE 1', 'EE 2']
E       AssertionError: assert None == ['HoD 2', 'EE 1', 'EE 2']

test_student.py:125: AssertionError
______________________________ test_s_hierarchy_3 ______________________________

    def test_s_hierarchy_3():
        t_d = get_hier()
        try:
            t_d.find_people_in_hierarchy('Accountant')
>           raise AssertionError("Expecting a ValueError when node is not found.")
E           AssertionError: Expecting a ValueError when node is not found.

test_student.py:132: AssertionError
====================== 5 failed, 6 passed in 0.40 seconds ======================
============================= test session starts ==============================
platform linux -- Python 3.7.3, pytest-3.10.1, py-1.8.0, pluggy-0.12.0
rootdir: /media/an0nym0us/Essentilas/University/semester-3/data-structures/course-assignments/assignment6, inifile:
plugins: doctestplus-0.3.0, remotedata-0.3.1, openfiles-0.3.2, arraydiff-0.3, timeout-1.3.3
timeout: 3.0s
timeout method: signal
timeout func_only: False
collected 11 items

test_student.py ......FFFFF                                              [100%]

=================================== FAILURES ===================================
______________________________ test_s_collector_1 ______________________________

    def test_s_collector_1():
        t_d = get_hier()
        c = Collector()
>       t_d.left.dfs_apply(c.process)

test_student.py:106: 
_ _ _ _ _ _ _ _ _ _ _ _ _ _ _ _ _ _ _ _ _ _ _ _ _ _ _ _ _ _ _ _ _ _ _ _ _ _ _ _ 
a06.py:96: in dfs_apply
    fn(self)
_ _ _ _ _ _ _ _ _ _ _ _ _ _ _ _ _ _ _ _ _ _ _ _ _ _ _ _ _ _ _ _ _ _ _ _ _ _ _ _ 

self = <a06.Collector object at 0x7f59a93a29e8>
node = <a06.TreeNode object at 0x7f59a93a2f98>

    def process(self , node):
>       lst.append(node.val)
E       NameError: name 'lst' is not defined

a06.py:29: NameError
______________________________ test_s_collector_2 ______________________________

    def test_s_collector_2():
        t_d = get_hier()
        c = Collector()
>       t_d.left.left.dfs_apply(c.process)

test_student.py:112: 
_ _ _ _ _ _ _ _ _ _ _ _ _ _ _ _ _ _ _ _ _ _ _ _ _ _ _ _ _ _ _ _ _ _ _ _ _ _ _ _ 
a06.py:96: in dfs_apply
    fn(self)
_ _ _ _ _ _ _ _ _ _ _ _ _ _ _ _ _ _ _ _ _ _ _ _ _ _ _ _ _ _ _ _ _ _ _ _ _ _ _ _ 

self = <a06.Collector object at 0x7f59a93175f8>
node = <a06.TreeNode object at 0x7f59a9317518>

    def process(self , node):
>       lst.append(node.val)
E       NameError: name 'lst' is not defined

a06.py:29: NameError
______________________________ test_s_hierarchy_1 ______________________________

    def test_s_hierarchy_1():
        t_d = get_hier()
        l = t_d.find_people_in_hierarchy('Director')
>       assert l == ['Director', 'HoD 1', 'CS 1', 'CS 2', 'HoD 2', 'EE 1', 'EE 2']
E       AssertionError: assert None == ['Director', 'HoD 1', 'CS 1', 'CS 2', 'HoD 2', 'EE 1', ...]

test_student.py:119: AssertionError
______________________________ test_s_hierarchy_2 ______________________________

    def test_s_hierarchy_2():
        t_d = get_hier()
        l = t_d.find_people_in_hierarchy('HoD 2')
>       assert l == ['HoD 2', 'EE 1', 'EE 2']
E       AssertionError: assert None == ['HoD 2', 'EE 1', 'EE 2']

test_student.py:125: AssertionError
______________________________ test_s_hierarchy_3 ______________________________

    def test_s_hierarchy_3():
        t_d = get_hier()
        try:
            t_d.find_people_in_hierarchy('Accountant')
>           raise AssertionError("Expecting a ValueError when node is not found.")
E           AssertionError: Expecting a ValueError when node is not found.

test_student.py:132: AssertionError
====================== 5 failed, 6 passed in 0.12 seconds ======================
============================= test session starts ==============================
platform linux -- Python 3.7.3, pytest-3.10.1, py-1.8.0, pluggy-0.12.0
rootdir: /media/an0nym0us/Essentilas/University/semester-3/data-structures/course-assignments/assignment6, inifile:
plugins: doctestplus-0.3.0, remotedata-0.3.1, openfiles-0.3.2, arraydiff-0.3, timeout-1.3.3
timeout: 3.0s
timeout method: signal
timeout func_only: False
collected 11 items

test_student.py ........FFF                                              [100%]

=================================== FAILURES ===================================
______________________________ test_s_hierarchy_1 ______________________________

    def test_s_hierarchy_1():
        t_d = get_hier()
        l = t_d.find_people_in_hierarchy('Director')
>       assert l == ['Director', 'HoD 1', 'CS 1', 'CS 2', 'HoD 2', 'EE 1', 'EE 2']
E       AssertionError: assert None == ['Director', 'HoD 1', 'CS 1', 'CS 2', 'HoD 2', 'EE 1', ...]

test_student.py:119: AssertionError
______________________________ test_s_hierarchy_2 ______________________________

    def test_s_hierarchy_2():
        t_d = get_hier()
        l = t_d.find_people_in_hierarchy('HoD 2')
>       assert l == ['HoD 2', 'EE 1', 'EE 2']
E       AssertionError: assert None == ['HoD 2', 'EE 1', 'EE 2']

test_student.py:125: AssertionError
______________________________ test_s_hierarchy_3 ______________________________

    def test_s_hierarchy_3():
        t_d = get_hier()
        try:
            t_d.find_people_in_hierarchy('Accountant')
>           raise AssertionError("Expecting a ValueError when node is not found.")
E           AssertionError: Expecting a ValueError when node is not found.

test_student.py:132: AssertionError
====================== 3 failed, 8 passed in 0.18 seconds ======================
============================= test session starts ==============================
platform linux -- Python 3.7.3, pytest-3.10.1, py-1.8.0, pluggy-0.12.0
rootdir: /media/an0nym0us/Essentilas/University/semester-3/data-structures/course-assignments/assignment6, inifile:
plugins: doctestplus-0.3.0, remotedata-0.3.1, openfiles-0.3.2, arraydiff-0.3, timeout-1.3.3
timeout: 3.0s
timeout method: signal
timeout func_only: False
collected 11 items

test_student.py ........FFF                                              [100%]

=================================== FAILURES ===================================
______________________________ test_s_hierarchy_1 ______________________________

    def test_s_hierarchy_1():
        t_d = get_hier()
        l = t_d.find_people_in_hierarchy('Director')
>       assert l == ['Director', 'HoD 1', 'CS 1', 'CS 2', 'HoD 2', 'EE 1', 'EE 2']
E       AssertionError: assert None == ['Director', 'HoD 1', 'CS 1', 'CS 2', 'HoD 2', 'EE 1', ...]

test_student.py:119: AssertionError
______________________________ test_s_hierarchy_2 ______________________________

    def test_s_hierarchy_2():
        t_d = get_hier()
        l = t_d.find_people_in_hierarchy('HoD 2')
>       assert l == ['HoD 2', 'EE 1', 'EE 2']
E       AssertionError: assert None == ['HoD 2', 'EE 1', 'EE 2']

test_student.py:125: AssertionError
______________________________ test_s_hierarchy_3 ______________________________

    def test_s_hierarchy_3():
        t_d = get_hier()
        try:
            t_d.find_people_in_hierarchy('Accountant')
>           raise AssertionError("Expecting a ValueError when node is not found.")
E           AssertionError: Expecting a ValueError when node is not found.

test_student.py:132: AssertionError
====================== 3 failed, 8 passed in 0.45 seconds ======================
============================= test session starts ==============================
platform linux -- Python 3.7.3, pytest-3.10.1, py-1.8.0, pluggy-0.12.0
rootdir: /media/an0nym0us/Essentilas/University/semester-3/data-structures/course-assignments/assignment6, inifile:
plugins: doctestplus-0.3.0, remotedata-0.3.1, openfiles-0.3.2, arraydiff-0.3, timeout-1.3.3
timeout: 3.0s
timeout method: signal
timeout func_only: False
collected 11 items

test_student.py ..........F                                              [100%]

=================================== FAILURES ===================================
______________________________ test_s_hierarchy_3 ______________________________

    def test_s_hierarchy_3():
        t_d = get_hier()
        try:
>           t_d.find_people_in_hierarchy('Accountant')

test_student.py:131: 
_ _ _ _ _ _ _ _ _ _ _ _ _ _ _ _ _ _ _ _ _ _ _ _ _ _ _ _ _ _ _ _ _ _ _ _ _ _ _ _ 

self = <a06.TreeNode object at 0x7fee7eeda2b0>, name = 'Accountant'

    def find_people_in_hierarchy(self, name):
    
        c = Collector()
        value = find_val(self , name)
>       value.dfs_apply(c.process)
E       AttributeError: 'NoneType' object has no attribute 'dfs_apply'

a06.py:141: AttributeError
===================== 1 failed, 10 passed in 0.38 seconds ======================
============================= test session starts ==============================
platform linux -- Python 3.7.3, pytest-3.10.1, py-1.8.0, pluggy-0.12.0
rootdir: /media/an0nym0us/Essentilas/University/semester-3/data-structures/course-assignments/assignment6, inifile:
plugins: doctestplus-0.3.0, remotedata-0.3.1, openfiles-0.3.2, arraydiff-0.3, timeout-1.3.3
timeout: 3.0s
timeout method: signal
timeout func_only: False
collected 11 items

test_student.py ...........                                              [100%]

========================== 11 passed in 0.05 seconds ===========================
